<?xml version="1.0"?>
<robot name="simple_joint_robot"
       xmlns:xacro="http://ros.org/wiki/xacro">

  <!-- Base link -->
  <link name="base_link">
    <visual>
      <geometry>
        <box size="0.1 0.1 0.1"/>
      </geometry>
    </visual>
  </link>

  <!-- Rotating link -->
  <link name="rotating_link">
    <visual>
      <geometry>
        <cylinder radius="0.05" length="0.2"/>
      </geometry>
      <origin xyz="0 0 0.1"/>
    </visual>
  </link>

  <!-- Revolute Joint -->
  <joint name="axial_joint" type="revolute">
    <parent link="base_link"/>
    <child link="rotating_link"/>
    <origin xyz="0 0 0" rpy="0 0 0"/>
    <axis xyz="0 0 1"/>
    <limit lower="-3.14" upper="3.14" effort="1.0" velocity="1.0"/>
  </joint>

  <!-- ros2_control plugin -->
  <ros2_control name="AxialJointHWSystem" type="system">
    <hardware>
      <plugin>rusmed_motors/AxialJointHW</plugin>
    </hardware>

    <joint name="axial_joint">
      <command_interface name="position"/>
      <state_interface name="position"/>
      <state_interface name="velocity"/>
    </joint>
  </ros2_control>

</robot>
